Workbook

Sheet MIS 2026
B1: QUALITY | E1: KEY TRADE DETAILS | W1: ISSUES OF THE DAY | X1: SALES DETAILS | AT1: L/C or ADVANCE DETAILS | BB1: SI, CERT, BAG MARKING INSTRUCTION & BUYER BANK DETAILS | BF1: SHIPMENT DETAILS | BV1: SALES INVOICING DETAILS | BY1: OBL TRACKING | CH1: CERT TRACKING | CL1: NEGO BANKING | CQ1: FINAL PAYMENT DETAILS | CS1: FNF STAGE | DL1: =SUBTOTAL(9,DL3:DL3) -> 0 | DQ1: =SUBTOTAL(9,DQ3:DQ3) -> 0 | DR1: =SUBTOTAL(9,DR3:DR3) -> 0 | DZ1: TRADE | EA1: =SUBTOTAL(9,EA3:EA3) -> 0 | EB1: POD QUALITY REPORT | EE1: PURCHASE DETAILS | EW1: PAYEMENT TO OTHER VENDORS | FL1: CYCLE TIME ( Need to Improve) | FS1: SAP ENTRIES
A2: TRADER STATUS | B2: KOR (Planned) | C2: NC | D2: Comm | E2: POSITION | F2: SAP SO ref | G2: Check | H2: BUYER NAME | I2: Origin | J2: Destination | K2: POD | L2: BL NO. | M2: BL/Stuffed Qty(MT) | N2: ETD/SOB | O2: ETA | P2: OBL Location | Q2: Crop / HBL | R2: CERT Location | S2: Nego Banking | T2: Origin Issue/Remarks | U2: Updates | V2: Addendums ( If Any) - With counterparty sign remark | W2: =TODAY() -> 46172 | X2: Deal Ticket Rcvd Date | Y2: SAP Deal Tkt No. | Z2: Sales Contract Dt. | AA2: SAP SO No. | AB2: Buyer Name | AC2: Shipment period | AD2: LDS | AE2: Toler% | AF2: Qty | AG2: Min Qty | AH2: UOM | AI2: Sales Price/ UOM | AJ2: Sales Contract value | AK2: Sales INCO | AL2: Sales - PMT Type | AM2: Adv % (TT) | AN2: 2nd Pmt % (DP/TT) | AO2: FNF % (TT) | AP2: PT DAYS | AQ2: Valency POC | AR2: Broker | AS2: Brokarage | AT2: LC No. | AU2: LC Issue date | AV2: Expiry Date | AW2: LDS as per LC | AX2: Bank | AY2: Adv Dates as per Contract | AZ2: Adv Amt | BA2: Adv Date | BB2: SI, CERT, BAG MARKING INSTRUCTION shared Date | BC2: Lot No: | BD2: IMPORTER Address on Certs | BE2: BUYER BANK DETAILS | BF2: SI, CERT, BAG MARKING INSTRUCTION shared Date | BG2: IMPORTER Address on Certs | BH2: BUYER BANK DETAILS | BI2: BL Number | BJ2: BL Net Wt./ Stuffed Qty | BK2: Conts Type | BL2: Conts Qty | BM2: SOB/ETD | BN2: Transhipment ETA | BO2: Final ETA | BP2: POL | BQ2: POD | BR2: Shipping Line | BS2: FREE DAYS AS PER BOOKING | BT2: VESSEL NAME | BU2: VOYAGE NO | BV2: Sales Invoice # -SAP | BW2: SAP Inv Date | BX2: SAP Sales Inv Amt | BY2: BL draft Recd/Sent | BZ2: OBL Final recd dt | CA2: OBL DHL Origin to SG | CB2: OBL Rcvd Date in SIG | CC2: OBL DHL SIG TO VIETNAM OR INDIA | CD2: OBL RCVD DATE AT DEST | CE2: OBL LOCATION | CF2: DHL -BL From SIG to Vietnam (Spcl case) | CG2: OBL Rcvd in Vietnam | CH2: Final Certs scan rcvd dt | CI2: Cert DHL no from Origin | CJ2: Cert Rcvd Date in Destination | CK2: CERTS Status | CL2: Nego Bank name | CM2: Nego Date | CN2: Bank to bank AWB details | CO2: Nego Docs in Buyer Bank Rcvd Date | CP2: Nego Status | CQ2: 98%/Final payment Amt | CR2: 98%/ Final Pmt Rcevd Date | CS2: VINA/RBS REPORT | CT2: LANDED QTY | CU2: QTY DIFFERENCE | CV2: % CHANGE | CW2: TOTAL AMOUNT RECEIVED TILL NOW ( ADV + MID ) | CX2: 2 % VALUE OF LANDED QTY | CY2: USD / LBS | CZ2: LANDED KOR | DA2: VARIANCE KOR | DB2: LANDED NC | DC2: VARIANCE NC | DD2: LANDED MOS% | DE2: VARIANCE MOS | DF2: QTY CLAIM | DG2: KOR CLAIM (FOR 1:1) | DH2: KOR CLAIM (FOR 1:2) | DI2: NC CLAIM | DJ2: MOS CLAIM | DK2: Total Qty & Qlty CLAIM | DL2: OTHER CLAIMS (IF ANY) | DM2: OTHER CLAIMS REMARKS | DN2: TOTAL F & F CLAIM | DO2: NET BILL VALUE | DP2: AMOUNT RECEIVED TILL NOW ( ADV + MID )2 | DQ2: NET PAYABLES | DR2: NET RECIVABLES | DS2: PAYABLE BY | DT2: CN/DN - REMARKS | DU2: SAP CN/DN No | DV2: SAP CN/DN INV No: | DW2: SAP Entries Completed Date | DX2: FNF INTERACTION WITH BUYER | DY2: F&F SAP STATUS | DZ2: CLOSE/OPEN | EA2: LOST PREMUIM CLAIM | EB2: Stuffed KOR | EC2: Stuffed NC | ED2: Stuffed MOIST | EE2: SAP PO No | EF2: PO Date | EG2: PI No. | EH2: Supplier | EI2: Valency /FOB | EJ2: Pur Qty (MT) | EK2: Pur Rate USD | EL2: Advance Amt. | EM2: Advance PMT Date | EN2: Order Value USD | EO2: Purchase INCO | EP2: Pur pmt Type | EQ2: Pur pmt Term | ER2: Bal Paid | ES2: Supplier Pmt Date | ET2: Delivery terms | EU2: Remarks (if Any) | EV2: Status for Cashflow | EW2: Freight Amt | EX2: Frt/Mt | EY2: Freight Inv recd dt | EZ2: Freight pmt date | FA2: Insurance no. | FB2: Insurance Dt | FC2: Comm $ | FD2: Total Comm Value (USD) | FE2: Comm - Sales Payment 1 | FF2: Comm - Sales Payment 2 | FG2: SAP Comm - Purch 3rd party | FH2: Deal Ticket Vs Contract | FI2: Contract Vs Advance | FL2: Freight Pmt VS Darft BL | FM2: Insurance Vs SOB) | FN2: OBL Copy Vs SOB) | FO2: Bank Nego Vs SOB | FP2: Certs Copy Vs SOB) | FQ2: ETD VS ETA | FR2: ETA Vs FNF Entries | FS2: Deal Ticket | FT2: SO | FU2: PO | FV2: MIGO | FW2: BATCH NO | FX2: MIR7 {Vendor} | FY2: MIR7 {Comm} | FZ2: MIR7 {Comm} | GA2: MIR7 {freight} | GB2: MIR7 {Ins} | GC2: OD | GD2: INVOICE | GE2: PI | GF2: Status | GG2: Remarks | GH2: Sale Retun VA01 | GI2: Sale Return VL01N | GJ2: Sale Return VF01 | GK2: Sale Debit/Credit Note VA01 | GL2: Sale Debit/Credit Inv VF01 | GM2: Pur Debit/Credit Note MIR7 | GN2: BL MIRROR COPY
A3: =IF(DZ3="CLOSE","Trade closed",IF(DZ3="PMT Pending","FNF Settlement is Due",IF(CS3<>0,"FNF Reconcillation Onging",IF(CR3<>0," Final Pmt Recd , FNF Pending",IF(CM3<>0,"Exp Dox Presented to Bank, Pmt Pending",IF(BZ3<>0,"OBL Scan Recd, Nego Pending",IF(BM3<>0,"Sailed, OBL & Certs Pending",IF(BJ3<>0,"Stuffed, Yet to Sail",IF(BB3<>0,"SI Sent, Shipment Awaited",IF(BA3<>0,"Advance Rcvd, SI Pending",IF(Z3<>0,"SC Raised, Advance Pending",IF(X3<>0,"Deal Ticket Rcvd SC Pending", "Entry Pending")))))))))))) -> Exp Dox Presented to Bank, Pmt Pending | B3: 51 | C3: 190 | D3: RCN | E3: =IF(AND(LEFT(TRIM(AA3&""),1)="3",BI3<>""),"CLOSE POSITION", IF(AND(LEFT(TRIM(AA3&""),1)="3",BI3=""),"SHORT POSITION", IF(AND(LEFT(TRIM(AA3&""),1)<>"3",BI3<>""),"LONG POSITION","ENTRY PENDING"))) -> CLOSE POSITION | F3: =AA3 -> 32014425 | H3: =AB3 -> VALENCY AGRO // HSS // ORGANIC FOODS INDIA EXIM | I3: NIGERIA(OGB) | J3: INDIA | K3: =IF(BQ3<>0,BQ3,"") -> TUTICORIN, INDIA | L3: =IF(BI3<>0,BI3,"") -> MEDULG618084 | M3: =IF(BJ3<>0,BJ3,"") -> 107.05 | N3: =IF(BM3<>0,BM3,"") -> 46090 | O3: =IF(BO3<>0,BO3,"") -> 46143 | P3: =CE3 -> OBL In Destination - INDIA | R3: =CK3 -> CERTS in Destination - INDIA | S3: =CP3 -> Docs in Buyer's Nego Bank | T3: =IFERROR(_xlfn.XLOOKUP(F3, '[2]Data 2026'!$H$12:$H$111, '[2]Data 2026'!$CL$12:$CL$111),"") | U3: Payment by Valency Agro will be done, 90 days after BL date- CARGO CLEARED. | V3: ADDENDUM 11/02-COUNTER SIGNED RCVD | X3: 46380 | Y3: 20009386 | Z3: 46380 | AA3: 32014425 | AB3: VALENCY AGRO // HSS // ORGANIC FOODS INDIA EXIM | AC3: BY 15TH MARCH | AD3: 46096 | AE3: 0.1 | AF3: 100 | AG3: =AF3*(1-AE3) -> 90 | AH3: MT | AI3: 1615 | AJ3: 161500 | AK3: CFR | AL3: 90 DAYS FROM BL DATE | AM3: 0 | AN3: 1 | AO3: 0 | AP3: 180 DAYS | AQ3: Mr.Chirag | AT3: - | AU3: - | AV3: - | AZ3: =AF3*AI3*AM3 -> 0 | BB3: 46030 | BF3: 46030 | BI3: MEDULG618084 | BJ3: 107.05 | BK3: 40' | BL3: 4 | BM3: 46090 | BN3: Hambantota, LK 26-04 | BO3: 46143 | BP3: Ogbomosho | BQ3: TUTICORIN, INDIA | BR3: MSC | BT3: MSC NISHA V - | BU3: FN608B | BV3: 90083238 | BX3: =BJ3*AI3 -> 172885.75 | BY3: 46126 | BZ3: 46122 | CA3: 4213158176 | CB3: 46126 | CE3: =IF(J3="VIETNAM", IF(CG3<>"","OBL in Vietnam Office", IF(CF3<>"","OBL in Transit from Vietnam Office", IF(CD3<>0,"OBL In Destination - "&J3, IF(CC3<>0,"OBL in Transit to Destination - "&J3, IF(CB3<>0,"OBL in SIG Office", IF(CA3<>0,"OBL in Transit from Origin to SIG", IF(BZ3<>0,"OBL in Origin - "&I3, IF(BY3<>0,"Draft Rcvd","No OBL Yet")))))))), IF(CO3<>0,"OBL In Destination - "&J3, IF(CM3<>0,"OBL in Transit with Nego Docs - "&J3, IF(CB3<>0,"OBL in SIG Office", IF(CA3<>0,"OBL in Transit from Origin to SIG", IF(BZ3<>0,"OBL in Origin - "&I3, IF(BY3<>0,"Draft Rcvd","No OBL Yet"))))))) -> OBL In Destination - INDIA | CH3: 46126 | CI3: 7012074694 | CJ3: 46125 | CK3: =IF(CJ3<>0,"CERTS in Destination - "&J3,IF(CI3<>0,"CERT in Transit to -"&J3,IF(CH3<>0,"CERT in Origin - "&I3,IF(CH3="","No CERTS Yet")))) -> CERTS in Destination - INDIA | CL3: ICICI BANK | CM3: 46126 | CN3: 5993795931 | CO3: 43922 | CP3: =IF(CO3<>0,"Docs in Buyer's Nego Bank",IF(CN3<>0,"Docs in Transit to Buyer's Nego Bank",IF(CM3<>0,"Docs in Our Nego Bank",IF(CL3="TT PAYMENT","Not Applicable","")))) -> Docs in Buyer's Nego Bank | CQ3: =(AN3*AI3*BJ3)-AZ3 -> 172885.75 | CU3: =IF(CS3="","",BJ3-CT3) | CV3: =IF(CS3="","",CU3/BJ3) | CW3: =IF(CS3="","",AZ3+CQ3) | CX3: =IF(CS3="","",BX3*2%) | CY3: =IF(CS3="","",AI3/B3) | DA3: =IF(CS3="","",B3-CZ3) | DC3: =IF(CS3="","",IF(CS3="","",DB3-C3)) | DE3: =IF(CS3="","",10%-DD3) | DF3: =IF(CS3="","",CU3*AI3) | DG3: =IF(CS3="","",IF(DA3>2,2*DA3*CT3*CY3,DA3*CT3*CY3)) | DH3: =IF(CS3="","",IF(DA3>2,2*(DA3-2*CT3*CY3),0)) | DI3: =IF(CS3="","",IF(DC3>0,DC3*0.5*CT3,0)) | DJ3: =IF(CS3="","",IF(DE3<0,DE3*CT3*AI3*1%,0)) | DK3: =IF(CS3="","",SUM(DF3:DJ3)) | DN3: =IF(CS3="","",SUM(DK3:DL3)) | DO3: =IF(CS3="","",BJ3*AI3-DN3) | DP3: =IF(CS3="","",AZ3+CQ3) | DQ3: =IF(CS3="","",IF((DP3-DO3)>0,DP3-DO3,"")) | DR3: =IF(CS3="","",IF((DO3-DP3)>0,(DO3-DP3),"")) | DS3: =IF(CS3="","",IF(DQ3="",H3,"VALENCY")) | DT3: =IF(DN3="","",IF(DN3>0,"CN", "DN")) | DY3: NO VINA/RBS REPORT | EA3: =IF(CS3="","", MIN(0,(IF(DA3>2,2,1)*DA3*CT3*CY3)) ) | EB3: 46.855 | EC3: 197 | ED3: 9 | EE3: 4900009449 | EH3: Valency Nigeria | EJ3: =BJ3 -> 107.05 | EK3: 2010 | EL3: - | EN3: =EK3*EJ3 -> 215170.5 | EO3: FOB | EV3: =IF(CR3<>0,"Final Pmt Recd",IF(CM3<>0,"Export Loan",IF(BZ3<>0,"Nego Pending",IF(Z3<>0,"Yet to load","Yet to load")))) -> Export Loan | EX3: =EW3/BJ3 -> 0 | EY3: Freight paid by origin | FD3: =FC3*BJ3 -> 0 | FL3: =IFERROR(EZ3-BY3,"") -> -46126 | FM3: =IFERROR(BM3-FB3,"") -> 46090 | FS3: 20009386 | FT3: 32014425 | FU3: 4900009449 | FV3: 5000271563 | FW3: 0000093574 | FX3: 5105710238 | GC3: 40081687 | GD3: 90083238 | GF3: done
A4: =IF(DZ4="CLOSE","Trade closed",IF(DZ4="PMT Pending","FNF Settlement is Due",IF(CS4<>0,"FNF Reconcillation Onging",IF(CR4<>0," Final Pmt Recd , FNF Pending",IF(CM4<>0,"Exp Dox Presented to Bank, Pmt Pending",IF(BZ4<>0,"OBL Scan Recd, Nego Pending",IF(BM4<>0,"Sailed, OBL & Certs Pending",IF(BJ4<>0,"Stuffed, Yet to Sail",IF(BB4<>0,"SI Sent, Shipment Awaited",IF(BA4<>0,"Advance Rcvd, SI Pending",IF(Z4<>0,"SC Raised, Advance Pending",IF(X4<>0,"Deal Ticket Rcvd SC Pending", "Entry Pending")))))))))))) -> Final Pmt Recd , FNF Pending | B4: 51 | C4: 190 | D4: RCN | E4: =IF(AND(LEFT(TRIM(AA4&""),1)="3",BI4<>""),"CLOSE POSITION", IF(AND(LEFT(TRIM(AA4&""),1)="3",BI4=""),"SHORT POSITION", IF(AND(LEFT(TRIM(AA4&""),1)<>"3",BI4<>""),"LONG POSITION","ENTRY PENDING"))) -> CLOSE POSITION | F4: =AA4 -> 32013748 | H4: =AB4 -> ST. PAULS CASHEW FACTORY | I4: NIGERIA(OGB) | J4: INDIA | K4: =IF(BQ4<>0,BQ4,"") -> TUTICORIN, INDIA | L4: =IF(BI4<>0,BI4,"") -> MEDULG619041 | M4: =IF(BJ4<>0,BJ4,"") -> 50.45 | N4: =IF(BM4<>0,BM4,"") -> 46099 | O4: =IF(BO4<>0,BO4,"") -> 46158 | P4: =CE4 -> OBL In Destination - INDIA | R4: =CK4 -> CERTS in Destination - INDIA | S4: =CP4 -> Docs in Buyer's Nego Bank | T4: =IFERROR(_xlfn.XLOOKUP(F4, '[2]Data 2026'!$H$12:$H$111, '[2]Data 2026'!$CL$12:$CL$111),"") | U4: PAYMENT RCVD 14/5 | V4: ADDENDUM 11/02-COUNTER SIGNED RCVD | X4: 46380 | Y4: 20009014 | Z4: 46017 | AA4: 32013748 | AB4: ST. PAULS CASHEW FACTORY | AC4: BY 15TH MARCH | AD4: 46096 | AE4: 0.1 | AF4: 50 | AG4: =AF4*(1-AE4) -> 45 | AH4: MT | AI4: 1610 | AJ4: =AI4*AF4 -> 80500 | AK4: CFR | AL4: DP SIGHT | AM4: 0 | AN4: 1 | AO4: 0 | AP4: 180 DAYS | AQ4: Mr. George | AT4: - | AU4: - | AV4: - | BA4: 46382 | BB4: 46030 | BF4: 46030 | BI4: MEDULG619041 | BJ4: 50.45 | BK4: 40' | BL4: 2 | BM4: 46099 | BN4: Colombo, LK 28-04, IN MSDU6442397 | BO4: 46158 | BP4: Ogbomosho | BQ4: TUTICORIN, INDIA | BR4: MSC | BT4: MSC TASMANIA | BU4: WP609R | BV4: 90083303 | BX4: =BJ4*AI4 -> 81224.5 | BZ4: 46120 | CA4: 4213158176 | CB4: 46126 | CE4: =IF(J4="VIETNAM", IF(CG4<>"","OBL in Vietnam Office", IF(CF4<>"","OBL in Transit from Vietnam Office", IF(CD4<>0,"OBL In Destination - "&J4, IF(CC4<>0,"OBL in Transit to Destination - "&J4, IF(CB4<>0,"OBL in SIG Office", IF(CA4<>0,"OBL in Transit from Origin to SIG", IF(BZ4<>0,"OBL in Origin - "&I4, IF(BY4<>0,"Draft Rcvd","No OBL Yet")))))))), IF(CO4<>0,"OBL In Destination - "&J4, IF(CM4<>0,"OBL in Transit with Nego Docs - "&J4, IF(CB4<>0,"OBL in SIG Office", IF(CA4<>0,"OBL in Transit from Origin to SIG", IF(BZ4<>0,"OBL in Origin - "&I4, IF(BY4<>0,"Draft Rcvd","No OBL Yet"))))))) -> OBL In Destination - INDIA | CH4: 46127 | CI4: 2574551980 | CJ4: 46133 | CK4: =IF(CJ4<>0,"CERTS in Destination - "&J4,IF(CI4<>0,"CERT in Transit to -"&J4,IF(CH4<>0,"CERT in Origin - "&I4,IF(CH4="","No CERTS Yet")))) -> CERTS in Destination - INDIA | CL4: HABIB BANK | CM4: 46128 | CN4: 4920872821 | CO4: 45017 | CP4: =IF(CO4<>0,"Docs in Buyer's Nego Bank",IF(CN4<>0,"Docs in Transit to Buyer's Nego Bank",IF(CM4<>0,"Docs in Our Nego Bank",IF(CL4="TT PAYMENT","Not Applicable","")))) -> Docs in Buyer's Nego Bank | CQ4: =(AN4*AI4*BJ4)-AZ4 -> 81224.5 | CR4: 46156 | CU4: =IF(CS4="","",BJ4-CT4) | CV4: =IF(CS4="","",CU4/BJ4) | CW4: =IF(CS4="","",AZ4+CQ4) | CX4: =IF(CS4="","",BX4*2%) | CY4: =IF(CS4="","",AI4/B4) | DA4: =IF(CS4="","",B4-CZ4) | DC4: =IF(CS4="","",IF(CS4="","",DB4-C4)) | DE4: =IF(CS4="","",10%-DD4) | DF4: =IF(CS4="","",CU4*AI4) | DG4: =IF(CS4="","",IF(DA4>2,2*DA4*CT4*CY4,DA4*CT4*CY4)) | DH4: =IF(CS4="","",IF(DA4>2,2*(DA4-2*CT4*CY4),0)) | DI4: =IF(CS4="","",IF(DC4>0,DC4*0.5*CT4,0)) | DJ4: =IF(CS4="","",IF(DE4<0,DE4*CT4*AI4*1%,0)) | DK4: =IF(CS4="","",SUM(DF4:DJ4)) | DN4: =IF(CS4="","",SUM(DK4:DL4)) | DO4: =IF(CS4="","",BJ4*AI4-DN4) | DP4: =IF(CS4="","",AZ4+CQ4) | DQ4: =IF(CS4="","",IF((DP4-DO4)>0,DP4-DO4,"")) | DR4: =IF(CS4="","",IF((DO4-DP4)>0,(DO4-DP4),"")) | DS4: =IF(CS4="","",IF(DQ4="",H4,"VALENCY")) | DT4: =IF(DN4="","",IF(DN4>0,"CN", "DN")) | DY4: NO VINA/RBS REPORT | EA4: =IF(CS4="","", MIN(0,(IF(DA4>2,2,1)*DA4*CT4*CY4)) ) | EB4: 46.735 | EC4: 197 | ED4: 8.95 | EE4: 4900009467 | EH4: Valency Nigeria | EJ4: =BJ4 -> 50.45 | EK4: 2010 | EL4: - | EN4: =EK4*EJ4 -> 101404.5 | EV4: =IF(CR4<>0,"Final Pmt Recd",IF(CM4<>0,"Export Loan",IF(BZ4<>0,"Nego Pending",IF(Z4<>0,"Yet to load","Yet to load")))) -> Final Pmt Recd | EX4: =EW4/BJ4 -> 0 | EY4: Freight paid by origin | FD4: =FC4*BJ4 -> 0 | FL4: =IFERROR(EZ4-BY4,"") -> 0 | FM4: =IFERROR(BM4-FB4,"") -> 46099 | FS4: 20009014 | FT4: 32013748 | FU4: 0 | GD4: 90083303 | GF4: done
A5: =IF(DZ5="CLOSE","Trade closed",IF(DZ5="PMT Pending","FNF Settlement is Due",IF(CS5<>0,"FNF Reconcillation Onging",IF(CR5<>0," Final Pmt Recd , FNF Pending",IF(CM5<>0,"Exp Dox Presented to Bank, Pmt Pending",IF(BZ5<>0,"OBL Scan Recd, Nego Pending",IF(BM5<>0,"Sailed, OBL & Certs Pending",IF(BJ5<>0,"Stuffed, Yet to Sail",IF(BB5<>0,"SI Sent, Shipment Awaited",IF(BA5<>0,"Advance Rcvd, SI Pending",IF(Z5<>0,"SC Raised, Advance Pending",IF(X5<>0,"Deal Ticket Rcvd SC Pending", "Entry Pending")))))))))))) -> Exp Dox Presented to Bank, Pmt Pending | B5: 47 | C5: 185 | D5: RCN | E5: =IF(AND(LEFT(TRIM(AA5&""),1)="3",BI5<>""),"CLOSE POSITION", IF(AND(LEFT(TRIM(AA5&""),1)="3",BI5=""),"SHORT POSITION", IF(AND(LEFT(TRIM(AA5&""),1)<>"3",BI5<>""),"LONG POSITION","ENTRY PENDING"))) -> CLOSE POSITION | F5: =AA5 -> 32015281-1 | H5: =AB5 -> Valency Agro (Processing) | I5: GHANA | J5: INDIA | K5: =IF(BQ5<>0,BQ5,"") -> MUNDRA, INDIA | L5: =IF(BI5<>0,BI5,"") -> TMA0158642 | M5: =IF(BJ5<>0,BJ5,"") -> 100 | N5: =IF(BM5<>0,BM5,"") -> 46099 | O5: =IF(BO5<>0,BO5,"") -> 46146 | P5: =CE5 -> OBL In Destination - INDIA | R5: =CK5 -> CERTS in Destination - INDIA | S5: =CP5 -> Docs in Buyer's Nego Bank | T5: =IFERROR(_xlfn.XLOOKUP(F5, '[2]Data 2026'!$H$12:$H$111, '[2]Data 2026'!$CL$12:$CL$111),"") | U5: Payment by Valency Agro will be done, 90 days after BL date- CARGO CLEARED. | X5: 46093 | Y5: 20009747 | Z5: =X5 -> 46093 | AA5: 32015281-1 | AB5: Valency Agro (Processing) | AC5: March - 26 | AD5: 46112 | AE5: 0.1 | AF5: 100 | AG5: =AF5*(1-AE5) -> 90 | AH5: MT | AI5: 1585 | AJ5: =AI5*AF5 -> 158500 | AK5: CIF | AL5: 90 DAYS FROM BL DATE | AM5: 0 | AN5: 1 | AO5: 0 | AP5: 180 DAYS | AQ5: Mr. Naveen | AR5: Direct | AT5: - | AU5: - | AV5: - | AZ5: =AF5*AI5*AM5 -> 0 | BA5: =Z5 -> 46093 | BB5: 46078 | BF5: 46078 | BI5: TMA0158642 | BJ5: 100 | BK5: 40' | BL5: 4 | BM5: 46099 | BO5: 46146 | BP5: GHANA | BQ5: MUNDRA, INDIA | BR5: CMA CGM | BT5: MAERSK HANGZHOU | BU5: 0WWQ0E1MA | BV5: 90082901 | BX5: =BJ5*AI5 -> 158500 | BZ5: 46121 | CA5: 5548360370 | CB5: 46126 | CE5: =IF(J5="VIETNAM", IF(CG5<>"","OBL in Vietnam Office", IF(CF5<>"","OBL in Transit from Vietnam Office", IF(CD5<>0,"OBL In Destination - "&J5, IF(CC5<>0,"OBL in Transit to Destination - "&J5, IF(CB5<>0,"OBL in SIG Office", IF(CA5<>0,"OBL in Transit from Origin to SIG", IF(BZ5<>0,"OBL in Origin - "&I5, IF(BY5<>0,"Draft Rcvd","No OBL Yet")))))))), IF(CO5<>0,"OBL In Destination - "&J5, IF(CM5<>0,"OBL in Transit with Nego Docs - "&J5, IF(CB5<>0,"OBL in SIG Office", IF(CA5<>0,"OBL in Transit from Origin to SIG", IF(BZ5<>0,"OBL in Origin - "&I5, IF(BY5<>0,"Draft Rcvd","No OBL Yet"))))))) -> OBL In Destination - INDIA | CH5: 46146 | CI5: 2243774470 | CJ5: 46153 | CK5: =IF(CJ5<>0,"CERTS in Destination - "&J5,IF(CI5<>0,"CERT in Transit to -"&J5,IF(CH5<>0,"CERT in Origin - "&I5,IF(CH5="","No CERTS Yet")))) -> CERTS in Destination - INDIA | CL5: ICICI BANK | CM5: 46126 | CN5: 5993795931 | CO5: 43922 | CP5: =IF(CO5<>0,"Docs in Buyer's Nego Bank",IF(CN5<>0,"Docs in Transit to Buyer's Nego Bank",IF(CM5<>0,"Docs in Our Nego Bank",IF(CL5="TT PAYMENT","Not Applicable","")))) -> Docs in Buyer's Nego Bank | CQ5: =(AN5*AI5*BJ5)-AZ5 -> 158500 | CU5: =IF(CS5="","",BJ5-CT5) | CV5: =IF(CS5="","",CU5/BJ5) | CW5: =IF(CS5="","",AZ5+CQ5) | CX5: =IF(CS5="","",BX5*2%) | CY5: =IF(CS5="","",AI5/B5) | DA5: =IF(CS5="","",B5-CZ5) | DC5: =IF(CS5="","",IF(CS5="","",DB5-C5)) | DE5: =IF(CS5="","",10%-DD5) | DF5: =IF(CS5="","",CU5*AI5) | DG5: =IF(CS5="","",IF(DA5>2,2*DA5*CT5*CY5,DA5*CT5*CY5)) | DH5: =IF(CS5="","",IF(DA5>2,2*(DA5-2*CT5*CY5),0)) | DI5: =IF(CS5="","",IF(DC5>0,DC5*0.5*CT5,0)) | DJ5: =IF(CS5="","",IF(DE5<0,DE5*CT5*AI5*1%,0)) | DK5: =IF(CS5="","",SUM(DF5:DJ5)) | DN5: =IF(CS5="","",SUM(DK5:DL5)) | DO5: =IF(CS5="","",BJ5*AI5-DN5) | DP5: =IF(CS5="","",AZ5+CQ5) | DQ5: =IF(CS5="","",IF((DP5-DO5)>0,DP5-DO5,"")) | DR5: =IF(CS5="","",IF((DO5-DP5)>0,(DO5-DP5),"")) | DS5: =IF(CS5="","",IF(DQ5="",H5,"VALENCY")) | DT5: =IF(DN5="","",IF(DN5>0,"CN", "DN")) | DY5: NO VINA/RBS REPORT | EA5: =IF(CS5="","", MIN(0,(IF(DA5>2,2,1)*DA5*CT5*CY5)) ) | EB5: =_xleta.IF -> #VALUE! | EH5: Valora Exim | EI5: FOB | EN5: =EK5*EJ5 -> 0 | EV5: =IF(CR5<>0,"Final Pmt Recd",IF(CM5<>0,"Export Loan",IF(BZ5<>0,"Nego Pending",IF(Z5<>0,"Yet to load","Yet to load")))) -> Export Loan | EX5: =EW5/BJ5 -> 0 | EY5: Freight paid by origin | FD5: =FC5*BJ5 -> 0 | FL5: =IFERROR(EZ5-BY5,"") -> 0 | FM5: =IFERROR(BM5-FB5,"") -> 46099 | FS5: =Y5 -> 20009747 | FT5: =AA5 -> 32015281-1 | GD5: 90082901 | GF5: done
A6: =IF(DZ6="CLOSE","Trade closed",IF(DZ6="PMT Pending","FNF Settlement is Due",IF(CS6<>0,"FNF Reconcillation Onging",IF(CR6<>0," Final Pmt Recd , FNF Pending",IF(CM6<>0,"Exp Dox Presented to Bank, Pmt Pending",IF(BZ6<>0,"OBL Scan Recd, Nego Pending",IF(BM6<>0,"Sailed, OBL & Certs Pending",IF(BJ6<>0,"Stuffed, Yet to Sail",IF(BB6<>0,"SI Sent, Shipment Awaited",IF(BA6<>0,"Advance Rcvd, SI Pending",IF(Z6<>0,"SC Raised, Advance Pending",IF(X6<>0,"Deal Ticket Rcvd SC Pending", "Entry Pending")))))))))))) -> SI Sent, Shipment Awaited | B6: 49 | C6: 200 | D6: RCN | E6: =IF(AND(LEFT(TRIM(AA6&""),1)="3",BI6<>""),"CLOSE POSITION", IF(AND(LEFT(TRIM(AA6&""),1)="3",BI6=""),"SHORT POSITION", IF(AND(LEFT(TRIM(AA6&""),1)<>"3",BI6<>""),"LONG POSITION","ENTRY PENDING"))) -> SHORT POSITION | F6: =AA6 -> 32014480 | H6: =AB6 -> AMITH CASHEWS PVT LTD | I6: IVC | J6: INDIA | K6: =IF(BQ6<>0,BQ6,"") -> MANGALORE, INDIA | L6: =IF(BI6<>0,BI6,"") | M6: =IF(BJ6<>0,BJ6,"") | N6: =IF(BM6<>0,BM6,"") | O6: =IF(BO6<>0,BO6,"") | P6: =CE6 -> No OBL Yet | R6: =CK6 -> No CERTS Yet | S6: =CP6 | T6: CLARIFICATION ON LATEST SOB | U6: 267489694 | X6: 46072 | Y6: 20009532 | Z6: 46072 | AA6: 32014480 | AB6: AMITH CASHEWS PVT LTD | AC6: April - 26 | AD6: 46142 | AE6: 0.1 | AF6: 100 | AG6: =AF6*(1-AE6) -> 90 | AH6: MT | AI6: 1545 | AJ6: =AI6*AF6 -> 154500 | AK6: CIF | AL6: DP SIGHT | AM6: 0.1 | AN6: 0.9 | AO6: 0 | AP6: 180 DAYS | AQ6: Mr. George | AR6: Mr. Rao | AS6: 5 | AU6: - | AV6: - | AY6: 46078 | AZ6: =AF6*AI6*AM6 -> 15450 | BA6: 46086 | BB6: 46083 | BF6: 46083 | BK6: 40' | BP6: IVC | BQ6: MANGALORE, INDIA | BX6: =BJ6*AI6 -> 0 | CE6: =IF(J6="VIETNAM", IF(CG6<>"","OBL in Vietnam Office", IF(CF6<>"","OBL in Transit from Vietnam Office", IF(CD6<>0,"OBL In Destination - "&J6, IF(CC6<>0,"OBL in Transit to Destination - "&J6, IF(CB6<>0,"OBL in SIG Office", IF(CA6<>0,"OBL in Transit from Origin to SIG", IF(BZ6<>0,"OBL in Origin - "&I6, IF(BY6<>0,"Draft Rcvd","No OBL Yet")))))))), IF(CO6<>0,"OBL In Destination - "&J6, IF(CM6<>0,"OBL in Transit with Nego Docs - "&J6, IF(CB6<>0,"OBL in SIG Office", IF(CA6<>0,"OBL in Transit from Origin to SIG", IF(BZ6<>0,"OBL in Origin - "&I6, IF(BY6<>0,"Draft Rcvd","No OBL Yet"))))))) -> No OBL Yet | CK6: =IF(CJ6<>0,"CERTS in Destination - "&J6,IF(CI6<>0,"CERT in Transit to -"&J6,IF(CH6<>0,"CERT in Origin - "&I6,IF(CH6="","No CERTS Yet")))) -> No CERTS Yet | CP6: =IF(CO6<>0,"Docs in Buyer's Nego Bank",IF(CN6<>0,"Docs in Transit to Buyer's Nego Bank",IF(CM6<>0,"Docs in Our Nego Bank",IF(CL6="TT PAYMENT","Not Applicable","")))) | CQ6: =(AN6*AI6*BJ6)-AZ6 -> -15450 | CU6: =IF(CS6="","",BJ6-CT6) | CV6: =IF(CS6="","",CU6/BJ6) | CW6: =IF(CS6="","",AZ6+CQ6) | CX6: =IF(CS6="","",BX6*2%) | CY6: =IF(CS6="","",AI6/B6) | DA6: =IF(CS6="","",B6-CZ6) | DC6: =IF(CS6="","",IF(CS6="","",DB6-C6)) | DE6: =IF(CS6="","",10%-DD6) | DF6: =IF(CS6="","",CU6*AI6) | DG6: =IF(CS6="","",IF(DA6>2,2*DA6*CT6*CY6,DA6*CT6*CY6)) | DH6: =IF(CS6="","",IF(DA6>2,2*(DA6-2*CT6*CY6),0)) | DI6: =IF(CS6="","",IF(DC6>0,DC6*0.5*CT6,0)) | DJ6: =IF(CS6="","",IF(DE6<0,DE6*CT6*AI6*1%,0)) | DK6: =IF(CS6="","",SUM(DF6:DJ6)) | DN6: =IF(CS6="","",SUM(DK6:DL6)) | DO6: =IF(CS6="","",BJ6*AI6-DN6) | DP6: =IF(CS6="","",AZ6+CQ6) | DQ6: =IF(CS6="","",IF((DP6-DO6)>0,DP6-DO6,"")) | DR6: =IF(CS6="","",IF((DO6-DP6)>0,(DO6-DP6),"")) | DS6: =IF(CS6="","",IF(DQ6="",H6,"VALENCY")) | DT6: =IF(DN6="","",IF(DN6>0,"CN", "DN")) | DY6: NO VINA/RBS REPORT | EA6: =IF(CS6="","", MIN(0,(IF(DA6>2,2,1)*DA6*CT6*CY6)) ) | EH6: VALENCY IVC | EN6: =EK6*EJ6 -> 0 | EV6: =IF(CR6<>0,"Final Pmt Recd",IF(CM6<>0,"Export Loan",IF(BZ6<>0,"Nego Pending",IF(Z6<>0,"Yet to load","Yet to load")))) -> Yet to load | EX6: =EW6/BJ6 -> #DIV/0! | EY6: Freight paid by origin | FD6: =FC6*BJ6 -> 0 | FL6: =IFERROR(EZ6-BY6,"") -> 0 | FM6: =IFERROR(BM6-FB6,"") -> 0 | FS6: =Y6 -> 20009532 | FT6: =AA6 -> 32014480
A7: =IF(DZ7="CLOSE","Trade closed",IF(DZ7="PMT Pending","FNF Settlement is Due",IF(CS7<>0,"FNF Reconcillation Onging",IF(CR7<>0," Final Pmt Recd , FNF Pending",IF(CM7<>0,"Exp Dox Presented to Bank, Pmt Pending",IF(BZ7<>0,"OBL Scan Recd, Nego Pending",IF(BM7<>0,"Sailed, OBL & Certs Pending",IF(BJ7<>0,"Stuffed, Yet to Sail",IF(BB7<>0,"SI Sent, Shipment Awaited",IF(BA7<>0,"Advance Rcvd, SI Pending",IF(Z7<>0,"SC Raised, Advance Pending",IF(X7<>0,"Deal Ticket Rcvd SC Pending", "Entry Pending")))))))))))) -> SI Sent, Shipment Awaited | B7: 48 | C7: 200 | D7: RCN | E7: =IF(AND(LEFT(TRIM(AA7&""),1)="3",BI7<>""),"CLOSE POSITION", IF(AND(LEFT(TRIM(AA7&""),1)="3",BI7=""),"SHORT POSITION", IF(AND(LEFT(TRIM(AA7&""),1)<>"3",BI7<>""),"LONG POSITION","ENTRY PENDING"))) -> CLOSE POSITION | F7: =AA7 -> 32014497 | H7: =AB7 -> FAVOURITE CASHEWS | I7: IVC | J7: INDIA | K7: =IF(BQ7<>0,BQ7,"") -> MANGALORE, INDIA | L7: =IF(BI7<>0,BI7,"") -> 267489852 | M7: =IF(BJ7<>0,BJ7,"") | N7: =IF(BM7<>0,BM7,"") | O7: =IF(BO7<>0,BO7,"") -> 46202 | P7: =CE7 -> No OBL Yet | R7: =CK7 -> No CERTS Yet | S7: =CP7 | T7: CLARIFICATION ON LATEST SOB | U7: ADVANCE RCVD 10/03- 267489852 | X7: 46076 | Y7: 20009551 | Z7: 46074 | AA7: 32014497 | AB7: FAVOURITE CASHEWS | AC7: April - 26 | AD7: 46142 | AE7: 0.1 | AF7: 200 | AG7: =AF7*(1-AE7) -> 180 | AH7: MT | AI7: 1510 | AJ7: =AI7*AF7 -> 302000 | AK7: CIF | AL7: DP SIGHT | AM7: 0.1 | AN7: 0.9 | AO7: 0 | AP7: 180 DAYS | AQ7: Mr. George | AR7: Mr. Rao | AS7: 5 | AT7: - | AU7: - | AV7: - | AZ7: =AF7*AI7*AM7 -> 30200 | BA7: 46091 | BB7: 46083 | BF7: 46083 | BI7: 267489852 | BK7: 40' | BO7: 46202 | BP7: IVC | BQ7: MANGALORE, INDIA | BX7: =BJ7*AI7 -> 0 | CE7: =IF(J7="VIETNAM", IF(CG7<>"","OBL in Vietnam Office", IF(CF7<>"","OBL in Transit from Vietnam Office", IF(CD7<>0,"OBL In Destination - "&J7, IF(CC7<>0,"OBL in Transit to Destination - "&J7, IF(CB7<>0,"OBL in SIG Office", IF(CA7<>0,"OBL in Transit from Origin to SIG", IF(BZ7<>0,"OBL in Origin - "&I7, IF(BY7<>0,"Draft Rcvd","No OBL Yet")))))))), IF(CO7<>0,"OBL In Destination - "&J7, IF(CM7<>0,"OBL in Transit with Nego Docs - "&J7, IF(CB7<>0,"OBL in SIG Office", IF(CA7<>0,"OBL in Transit from Origin to SIG", IF(BZ7<>0,"OBL in Origin - "&I7, IF(BY7<>0,"Draft Rcvd","No OBL Yet"))))))) -> No OBL Yet | CK7: =IF(CJ7<>0,"CERTS in Destination - "&J7,IF(CI7<>0,"CERT in Transit to -"&J7,IF(CH7<>0,"CERT in Origin - "&I7,IF(CH7="","No CERTS Yet")))) -> No CERTS Yet | CP7: =IF(CO7<>0,"Docs in Buyer's Nego Bank",IF(CN7<>0,"Docs in Transit to Buyer's Nego Bank",IF(CM7<>0,"Docs in Our Nego Bank",IF(CL7="TT PAYMENT","Not Applicable","")))) | CQ7: =(AN7*AI7*BJ7)-AZ7 -> -30200 | CU7: =IF(CS7="","",BJ7-CT7) | CV7: =IF(CS7="","",CU7/BJ7) | CW7: =IF(CS7="","",AZ7+CQ7) | CX7: =IF(CS7="","",BX7*2%) | CY7: =IF(CS7="","",AI7/B7) | DA7: =IF(CS7="","",B7-CZ7) | DC7: =IF(CS7="","",IF(CS7="","",DB7-C7)) | DE7: =IF(CS7="","",10%-DD7) | DF7: =IF(CS7="","",CU7*AI7) | DG7: =IF(CS7="","",IF(DA7>2,2*DA7*CT7*CY7,DA7*CT7*CY7)) | DH7: =IF(CS7="","",IF(DA7>2,2*(DA7-2*CT7*CY7),0)) | DI7: =IF(CS7="","",IF(DC7>0,DC7*0.5*CT7,0)) | DJ7: =IF(CS7="","",IF(DE7<0,DE7*CT7*AI7*1%,0)) | DK7: =IF(CS7="","",SUM(DF7:DJ7)) | DN7: =IF(CS7="","",SUM(DK7:DL7)) | DO7: =IF(CS7="","",BJ7*AI7-DN7) | DP7: =IF(CS7="","",AZ7+CQ7) | DQ7: =IF(CS7="","",IF((DP7-DO7)>0,DP7-DO7,"")) | DR7: =IF(CS7="","",IF((DO7-DP7)>0,(DO7-DP7),"")) | DS7: =IF(CS7="","",IF(DQ7="",H7,"VALENCY")) | DT7: =IF(DN7="","",IF(DN7>0,"CN", "DN")) | DY7: NO VINA/RBS REPORT | EA7: =IF(CS7="","", MIN(0,(IF(DA7>2,2,1)*DA7*CT7*CY7)) ) | EH7: VALENCY IVC | EN7: =EK7*EJ7 -> 0 | EV7: =IF(CR7<>0,"Final Pmt Recd",IF(CM7<>0,"Export Loan",IF(BZ7<>0,"Nego Pending",IF(Z7<>0,"Yet to load","Yet to load")))) -> Yet to load | EX7: =EW7/BJ7 -> #DIV/0! | EY7: Freight paid by origin | FD7: =FC7*BJ7 -> 0 | FL7: =IFERROR(EZ7-BY7,"") -> 0 | FM7: =IFERROR(BM7-FB7,"") -> 0 | FS7: =Y7 -> 20009551 | FT7: =AA7 -> 32014497
A8: =IF(DZ8="CLOSE","Trade closed",IF(DZ8="PMT Pending","FNF Settlement is Due",IF(CS8<>0,"FNF Reconcillation Onging",IF(CR8<>0," Final Pmt Recd , FNF Pending",IF(CM8<>0,"Exp Dox Presented to Bank, Pmt Pending",IF(BZ8<>0,"OBL Scan Recd, Nego Pending",IF(BM8<>0,"Sailed, OBL & Certs Pending",IF(BJ8<>0,"Stuffed, Yet to Sail",IF(BB8<>0,"SI Sent, Shipment Awaited",IF(BA8<>0,"Advance Rcvd, SI Pending",IF(Z8<>0,"SC Raised, Advance Pending",IF(X8<>0,"Deal Ticket Rcvd SC Pending", "Entry Pending")))))))))))) -> OBL Scan Recd, Nego Pending | B8: 49 | C8: 185 | D8: RCN | E8: =IF(AND(LEFT(TRIM(AA8&""),1)="3",BI8<>""),"CLOSE POSITION", IF(AND(LEFT(TRIM(AA8&""),1)="3",BI8=""),"SHORT POSITION", IF(AND(LEFT(TRIM(AA8&""),1)<>"3",BI8<>""),"LONG POSITION","ENTRY PENDING"))) -> CLOSE POSITION | F8: =AA8 -> 32015806-1 | H8: =AB8 -> INDIA ENTERPRISES | I8: NIGERIA(SAKI) | J8: INDIA | K8: =IF(BQ8<>0,BQ8,"") -> MANGALORE, INDIA | L8: =IF(BI8<>0,BI8,"") -> MEDULG632861 | M8: =IF(BJ8<>0,BJ8,"") -> 100.48 | N8: =IF(BM8<>0,BM8,"") -> 46158 | O8: =IF(BO8<>0,BO8,"") -> 46193 | P8: =CE8 -> OBL in Origin - NIGERIA(SAKI) | R8: =CK8 -> No CERTS Yet | S8: =CP8 | T8: OBL Expected on 25/5 | U8: OBL RCVD 25/5- CERT PENDING | V8: ADDENDUM 01-EXTENSION TILL 15TH MAY | W8: OBL COURRIER PENDING | X8: 46090 | Y8: 20009815 | Z8: 46104 | AA8: 32015806-1 | AB8: INDIA ENTERPRISES | AC8: April - 26 | AD8: 46157 | AE8: 0.1 | AF8: 100 | AG8: =AF8*(1-AE8) -> 90 | AH8: MT | AI8: 1575 | AJ8: 315000 | AK8: CIF | AL8: DP SIGHT | AM8: 0.1 | AN8: 0.9 | AO8: 0 | AP8: 180 DAYS | AQ8: Mr. George | AT8: - | AU8: - | AV8: - | AY8: 46094 | AZ8: =AF8*AI8*AM8 -> 15750 | BA8: 46106 | BB8: 46094 | BI8: MEDULG632861 | BJ8: 100.48 | BK8: 40' | BM8: 46158 | BN8: DFSU6311600 | BO8: 46193 | BP8: NIGERIA | BQ8: MANGALORE, INDIA | BR8: MSC | BX8: =BJ8*AI8 -> 158256 | BZ8: 46168 | CE8: =IF(J8="VIETNAM", IF(CG8<>"","OBL in Vietnam Office", IF(CF8<>"","OBL in Transit from Vietnam Office", IF(CD8<>0,"OBL In Destination - "&J8, IF(CC8<>0,"OBL in Transit to Destination - "&J8, IF(CB8<>0,"OBL in SIG Office", IF(CA8<>0,"OBL in Transit from Origin to SIG", IF(BZ8<>0,"OBL in Origin - "&I8, IF(BY8<>0,"Draft Rcvd","No OBL Yet")))))))), IF(CO8<>0,"OBL In Destination - "&J8, IF(CM8<>0,"OBL in Transit with Nego Docs - "&J8, IF(CB8<>0,"OBL in SIG Office", IF(CA8<>0,"OBL in Transit from Origin to SIG", IF(BZ8<>0,"OBL in Origin - "&I8, IF(BY8<>0,"Draft Rcvd","No OBL Yet"))))))) -> OBL in Origin - NIGERIA(SAKI) | CK8: =IF(CJ8<>0,"CERTS in Destination - "&J8,IF(CI8<>0,"CERT in Transit to -"&J8,IF(CH8<>0,"CERT in Origin - "&I8,IF(CH8="","No CERTS Yet")))) -> No CERTS Yet | CP8: =IF(CO8<>0,"Docs in Buyer's Nego Bank",IF(CN8<>0,"Docs in Transit to Buyer's Nego Bank",IF(CM8<>0,"Docs in Our Nego Bank",IF(CL8="TT PAYMENT","Not Applicable","")))) | CQ8: =(AN8*AI8*BJ8)-AZ8 -> 126680.4 | CU8: =IF(CS8="","",BJ8-CT8) | CV8: =IF(CS8="","",CU8/BJ8) | CW8: =IF(CS8="","",AZ8+CQ8) | CX8: =IF(CS8="","",BX8*2%) | CY8: =IF(CS8="","",AI8/B8) | DA8: =IF(CS8="","",B8-CZ8) | DC8: =IF(CS8="","",IF(CS8="","",DB8-C8)) | DE8: =IF(CS8="","",10%-DD8) | DF8: =IF(CS8="","",CU8*AI8) | DG8: =IF(CS8="","",IF(DA8>2,2*DA8*CT8*CY8,DA8*CT8*CY8)) | DH8: =IF(CS8="","",IF(DA8>2,2*(DA8-2*CT8*CY8),0)) | DI8: =IF(CS8="","",IF(DC8>0,DC8*0.5*CT8,0)) | DJ8: =IF(CS8="","",IF(DE8<0,DE8*CT8*AI8*1%,0)) | DK8: =IF(CS8="","",SUM(DF8:DJ8)) | DN8: =IF(CS8="","",SUM(DK8:DL8)) | DO8: =IF(CS8="","",BJ8*AI8-DN8) | DP8: =IF(CS8="","",AZ8+CQ8) | DQ8: =IF(CS8="","",IF((DP8-DO8)>0,DP8-DO8,"")) | DR8: =IF(CS8="","",IF((DO8-DP8)>0,(DO8-DP8),"")) | DS8: =IF(CS8="","",IF(DQ8="",H8,"VALENCY")) | DT8: =IF(DN8="","",IF(DN8>0,"CN", "DN")) | DY8: NO VINA/RBS REPORT | EA8: =IF(CS8="","", MIN(0,(IF(DA8>2,2,1)*DA8*CT8*CY8)) ) | EH8: Valency Nigeria | EN8: =EK8*EJ8 -> 0 | EV8: =IF(CR8<>0,"Final Pmt Recd",IF(CM8<>0,"Export Loan",IF(BZ8<>0,"Nego Pending",IF(Z8<>0,"Yet to load","Yet to load")))) -> Nego Pending | EX8: =EW8/BJ8 -> 0 | EY8: Freight paid by origin | FD8: =FC8*BJ8 -> 0 | FL8: =IFERROR(EZ8-BY8,"") -> 0 | FM8: =IFERROR(BM8-FB8,"") -> 46158 | FS8: =Y8 -> 20009815 | FT8: =AA8 -> 32015806-1
A9: =IF(DZ9="CLOSE","Trade closed",IF(DZ9="PMT Pending","FNF Settlement is Due",IF(CS9<>0,"FNF Reconcillation Onging",IF(CR9<>0," Final Pmt Recd , FNF Pending",IF(CM9<>0,"Exp Dox Presented to Bank, Pmt Pending",IF(BZ9<>0,"OBL Scan Recd, Nego Pending",IF(BM9<>0,"Sailed, OBL & Certs Pending",IF(BJ9<>0,"Stuffed, Yet to Sail",IF(BB9<>0,"SI Sent, Shipment Awaited",IF(BA9<>0,"Advance Rcvd, SI Pending",IF(Z9<>0,"SC Raised, Advance Pending",IF(X9<>0,"Deal Ticket Rcvd SC Pending", "Entry Pending")))))))))))) -> Sailed, OBL & Certs Pending | B9: 49 | C9: 185 | D9: RCN | E9: =IF(AND(LEFT(TRIM(AA9&""),1)="3",BI9<>""),"CLOSE POSITION", IF(AND(LEFT(TRIM(AA9&""),1)="3",BI9=""),"SHORT POSITION", IF(AND(LEFT(TRIM(AA9&""),1)<>"3",BI9<>""),"LONG POSITION","ENTRY PENDING"))) -> CLOSE POSITION | F9: =AA9 -> 32015806-2 | H9: =AB9 -> INDIA ENTERPRISES | I9: NIGERIA(SAKI) | J9: INDIA | K9: =IF(BQ9<>0,BQ9,"") -> MANGALORE, INDIA | L9: =IF(BI9<>0,BI9,"") -> MEDULG632812 | M9: =IF(BJ9<>0,BJ9,"") -> 99.989 | N9: =IF(BM9<>0,BM9,"") -> 46158 | O9: =IF(BO9<>0,BO9,"") -> 46193 | P9: =CE9 -> No OBL Yet | R9: =CK9 -> No CERTS Yet | S9: =CP9 | T9: OBL Expected on 25/5 | U9: PENDING OBL & CERTS-OBL EXPETCED 25/5 | V9: ADDENDUM 01-EXTENSION TILL 15TH MAY | W9: OBL EXPECTED 25/5 | X9: 46090 | Y9: 20009815 | Z9: 46104 | AA9: 32015806-2 | AB9: INDIA ENTERPRISES | AC9: April - 26 | AD9: 46157 | AE9: 0.1 | AF9: 100 | AG9: =AF9*(1-AE9) -> 90 | AH9: MT | AI9: 1575 | AJ9: 315000 | AK9: CIF | AL9: DP SIGHT | AM9: 0.1 | AN9: 0.9 | AO9: 0 | AP9: 180 DAYS | AQ9: Mr. George | AT9: - | AU9: - | AV9: - | AY9: 46094 | AZ9: =AF9*AI9*AM9 -> 15750 | BA9: 46106 | BB9: 46094 | BI9: MEDULG632812 | BJ9: 99.989 | BK9: 40' | BM9: 46158 | BN9: BMOU4009029 | BO9: 46193 | BP9: NIGERIA | BQ9: MANGALORE, INDIA | BR9: MSC | BX9: =BJ9*AI9 -> 157482.68 | CE9: =IF(J9="VIETNAM", IF(CG9<>"","OBL in Vietnam Office", IF(CF9<>"","OBL in Transit from Vietnam Office", IF(CD9<>0,"OBL In Destination - "&J9, IF(CC9<>0,"OBL in Transit to Destination - "&J9, IF(CB9<>0,"OBL in SIG Office", IF(CA9<>0,"OBL in Transit from Origin to SIG", IF(BZ9<>0,"OBL in Origin - "&I9, IF(BY9<>0,"Draft Rcvd","No OBL Yet")))))))), IF(CO9<>0,"OBL In Destination - "&J9, IF(CM9<>0,"OBL in Transit with Nego Docs - "&J9, IF(CB9<>0,"OBL in SIG Office", IF(CA9<>0,"OBL in Transit from Origin to SIG", IF(BZ9<>0,"OBL in Origin - "&I9, IF(BY9<>0,"Draft Rcvd","No OBL Yet"))))))) -> No OBL Yet | CK9: =IF(CJ9<>0,"CERTS in Destination - "&J9,IF(CI9<>0,"CERT in Transit to -"&J9,IF(CH9<>0,"CERT in Origin - "&I9,IF(CH9="","No CERTS Yet")))) -> No CERTS Yet | CP9: =IF(CO9<>0,"Docs in Buyer's Nego Bank",IF(CN9<>0,"Docs in Transit to Buyer's Nego Bank",IF(CM9<>0,"Docs in Our Nego Bank",IF(CL9="TT PAYMENT","Not Applicable","")))) | CQ9: =(AN9*AI9*BJ9)-AZ9 -> 125984.41 | CU9: =IF(CS9="","",BJ9-CT9) | CV9: =IF(CS9="","",CU9/BJ9) | CW9: =IF(CS9="","",AZ9+CQ9) | CX9: =IF(CS9="","",BX9*2%) | CY9: =IF(CS9="","",AI9/B9) | DA9: =IF(CS9="","",B9-CZ9) | DC9: =IF(CS9="","",IF(CS9="","",DB9-C9)) | DE9: =IF(CS9="","",10%-DD9) | DF9: =IF(CS9="","",CU9*AI9) | DG9: =IF(CS9="","",IF(DA9>2,2*DA9*CT9*CY9,DA9*CT9*CY9)) | DH9: =IF(CS9="","",IF(DA9>2,2*(DA9-2*CT9*CY9),0)) | DI9: =IF(CS9="","",IF(DC9>0,DC9*0.5*CT9,0)) | DJ9: =IF(CS9="","",IF(DE9<0,DE9*CT9*AI9*1%,0)) | DK9: =IF(CS9="","",SUM(DF9:DJ9)) | DN9: =IF(CS9="","",SUM(DK9:DL9)) | DO9: =IF(CS9="","",BJ9*AI9-DN9) | DP9: =IF(CS9="","",AZ9+CQ9) | DQ9: =IF(CS9="","",IF((DP9-DO9)>0,DP9-DO9,"")) | DR9: =IF(CS9="","",IF((DO9-DP9)>0,(DO9-DP9),"")) | DS9: =IF(CS9="","",IF(DQ9="",H9,"VALENCY")) | DT9: =IF(DN9="","",IF(DN9>0,"CN", "DN")) | DY9: NO VINA/RBS REPORT | EA9: =IF(CS9="","", MIN(0,(IF(DA9>2,2,1)*DA9*CT9*CY9)) ) | EH9: Valency Nigeria | EN9: =EK9*EJ9 -> 0 | EV9: =IF(CR9<>0,"Final Pmt Recd",IF(CM9<>0,"Export Loan",IF(BZ9<>0,"Nego Pending",IF(Z9<>0,"Yet to load","Yet to load")))) -> Yet to load | EX9: =EW9/BJ9 -> 0 | EY9: Freight paid by origin | FD9: =FC9*BJ9 -> 0 | FL9: =IFERROR(EZ9-BY9,"") -> 0 | FM9: =IFERROR(BM9-FB9,"") -> 46158 | FS9: =Y9 -> 20009815 | FT9: =AA9 -> 32015806-2
A10: =IF(DZ10="CLOSE","Trade closed",IF(DZ10="PMT Pending","FNF Settlement is Due",IF(CS10<>0,"FNF Reconcillation Onging",IF(CR10<>0," Final Pmt Recd , FNF Pending",IF(CM10<>0,"Exp Dox Presented to Bank, Pmt Pending",IF(BZ10<>0,"OBL Scan Recd, Nego Pending",IF(BM10<>0,"Sailed, OBL & Certs Pending",IF(BJ10<>0,"Stuffed, Yet to Sail",IF(BB10<>0,"SI Sent, Shipment Awaited",IF(BA10<>0,"Advance Rcvd, SI Pending",IF(Z10<>0,"SC Raised, Advance Pending",IF(X10<>0,"Deal Ticket Rcvd SC Pending", "Entry Pending")))))))))))) -> Exp Dox Presented to Bank, Pmt Pending | B10: 47 | C10: 185 | D10: RCN | E10: =IF(AND(LEFT(TRIM(AA10&""),1)="3",BI10<>""),"CLOSE POSITION", IF(AND(LEFT(TRIM(AA10&""),1)="3",BI10=""),"SHORT POSITION", IF(AND(LEFT(TRIM(AA10&""),1)<>"3",BI10<>""),"LONG POSITION","ENTRY PENDING"))) -> CLOSE POSITION | F10: =AA10 -> 32015281-4 | H10: =AB10 -> Valency Agro (Processing) | I10: GHANA | J10: INDIA | K10: =IF(BQ10<>0,BQ10,"") -> MUNDRA, INDIA | L10: =IF(BI10<>0,BI10,"") -> ONEYTEMG00306400 | M10: =IF(BJ10<>0,BJ10,"") -> 103.59 | N10: =IF(BM10<>0,BM10,"") -> 46103 | O10: =IF(BO10<>0,BO10,"") -> 46146 | P10: =CE10 -> OBL In Destination - INDIA | R10: =CK10 -> CERTS in Destination - INDIA | S10: =CP10 -> Docs in Buyer's Nego Bank | T10: =IFERROR(_xlfn.XLOOKUP(F10, '[2]Data 2026'!$H$12:$H$111, '[2]Data 2026'!$CL$12:$CL$111),"") | U10: Payment by Valency Agro will be done, 120 days after BL date- CARGO CLEARED. | X10: 46093 | Y10: 20009747 | Z10: =X10 -> 46093 | AA10: 32015281-4 | AB10: Valency Agro (Processing) | AC10: March - 26 | AD10: 46112 | AE10: 0.1 | AF10: 100 | AG10: =AF10*(1-AE10) -> 90 | AH10: MT | AI10: 1585 | AJ10: =AI10*AF10 -> 158500 | AK10: CIF | AL10: 120 DAYS FROM BL DATE | AM10: 0 | AN10: 1 | AO10: 0 | AP10: 180 DAYS | AQ10: Mr. Naveen | AR10: Direct | AT10: - | AU10: - | AV10: - | AZ10: =AF10*AI10*AM10 -> 0 | BA10: =Z10 -> 46093 | BB10: 46078 | BF10: 46078 | BI10: ONEYTEMG00306400 | BJ10: 103.59 | BK10: 40' | BL10: 4 | BM10: 46103 | BO10: 46146 | BP10: GHANA | BQ10: MUNDRA, INDIA | BR10: ONE LINE | BT10: GIALOVA | BU10: 2607E | BV10: 90082920 | BX10: =BJ10*AI10 -> 164190.15 | BZ10: 46122 | CB10: 46125 | CC10: 9016936213 | CD10: 46128 | CE10: =IF(J10="VIETNAM", IF(CG10<>"","OBL in Vietnam Office", IF(CF10<>"","OBL in Transit from Vietnam Office", IF(CD10<>0,"OBL In Destination - "&J10, IF(CC10<>0,"OBL in Transit to Destination - "&J10, IF(CB10<>0,"OBL in SIG Office", IF(CA10<>0,"OBL in Transit from Origin to SIG", IF(BZ10<>0,"OBL in Origin - "&I10, IF(BY10<>0,"Draft Rcvd","No OBL Yet")))))))), IF(CO10<>0,"OBL In Destination - "&J10, IF(CM10<>0,"OBL in Transit with Nego Docs - "&J10, IF(CB10<>0,"OBL in SIG Office", IF(CA10<>0,"OBL in Transit from Origin to SIG", IF(BZ10<>0,"OBL in Origin - "&I10, IF(BY10<>0,"Draft Rcvd","No OBL Yet"))))))) -> OBL In Destination - INDIA | CI10: 9016936213 | CJ10: 46128 | CK10: =IF(CJ10<>0,"CERTS in Destination - "&J10,IF(CI10<>0,"CERT in Transit to -"&J10,IF(CH10<>0,"CERT in Origin - "&I10,IF(CH10="","No CERTS Yet")))) -> CERTS in Destination - INDIA | CL10: ICICI BANK | CM10: 46125 | CN10: 9016936213 | CO10: 46128 | CP10: =IF(CO10<>0,"Docs in Buyer's Nego Bank",IF(CN10<>0,"Docs in Transit to Buyer's Nego Bank",IF(CM10<>0,"Docs in Our Nego Bank",IF(CL10="TT PAYMENT","Not Applicable","")))) -> Docs in Buyer's Nego Bank | CQ10: =(AN10*AI10*BJ10)-AZ10 -> 164190.15 | CU10: =IF(CS10="","",BJ10-CT10) | CV10: =IF(CS10="","",CU10/BJ10) | CW10: =IF(CS10="","",AZ10+CQ10) | CX10: =IF(CS10="","",BX10*2%) | CY10: =IF(CS10="","",AI10/B10) | DA10: =IF(CS10="","",B10-CZ10) | DC10: =IF(CS10="","",IF(CS10="","",DB10-C10)) | DE10: =IF(CS10="","",10%-DD10) | DF10: =IF(CS10="","",CU10*AI10) | DG10: =IF(CS10="","",IF(DA10>2,2*DA10*CT10*CY10,DA10*CT10*CY10)) | DH10: =IF(CS10="","",IF(DA10>2,2*(DA10-2*CT10*CY10),0)) | DI10: =IF(CS10="","",IF(DC10>0,DC10*0.5*CT10,0)) | DJ10: =IF(CS10="","",IF(DE10<0,DE10*CT10*AI10*1%,0)) | DK10: =IF(CS10="","",SUM(DF10:DJ10)) | DN10: =IF(CS10="","",SUM(DK10:DL10)) | DO10: =IF(CS10="","",BJ10*AI10-DN10) | DP10: =IF(CS10="","",AZ10+CQ10) | DQ10: =IF(CS10="","",IF((DP10-DO10)>0,DP10-DO10,"")) | DR10: =IF(CS10="","",IF((DO10-DP10)>0,(DO10-DP10),"")) | DS10: =IF(CS10="","",IF(DQ10="",H10,"VALENCY")) | DT10: =IF(DN10="","",IF(DN10>0,"CN", "DN")) | DY10: NO VINA/RBS REPORT | EA10: =IF(CS10="","", MIN(0,(IF(DA10>2,2,1)*DA10*CT10*CY10)) ) | EH10: Valora Exim | EI10: FOB | EN10: =EK10*EJ10 -> 0 | EV10: =IF(CR10<>0,"Final Pmt Recd",IF(CM10<>0,"Export Loan",IF(BZ10<>0,"Nego Pending",IF(Z10<>0,"Yet to load","Yet to load")))) -> Export Loan | EX10: =EW10/BJ10 -> 0 | EY10: Freight paid by origin | FD10: =FC10*BJ10 -> 0 | FL10: =IFERROR(EZ10-BY10,"") -> 0 | FM10: =IFERROR(BM10-FB10,"") -> 46103 | FS10: =Y10 -> 20009747 | FT10: =AA10 -> 32015281-4 | GD10: 90082920 | GF10: done
A11: =IF(DZ11="CLOSE","Trade closed",IF(DZ11="PMT Pending","FNF Settlement is Due",IF(CS11<>0,"FNF Reconcillation Onging",IF(CR11<>0," Final Pmt Recd , FNF Pending",IF(CM11<>0,"Exp Dox Presented to Bank, Pmt Pending",IF(BZ11<>0,"OBL Scan Recd, Nego Pending",IF(BM11<>0,"Sailed, OBL & Certs Pending",IF(BJ11<>0,"Stuffed, Yet to Sail",IF(BB11<>0,"SI Sent, Shipment Awaited",IF(BA11<>0,"Advance Rcvd, SI Pending",IF(Z11<>0,"SC Raised, Advance Pending",IF(X11<>0,"Deal Ticket Rcvd SC Pending", "Entry Pending")))))))))))) -> Final Pmt Recd , FNF Pending | B11: 47 | C11: 205 | D11: RCN | E11: =IF(AND(LEFT(TRIM(AA11&""),1)="3",BI11<>""),"CLOSE POSITION", IF(AND(LEFT(TRIM(AA11&""),1)="3",BI11=""),"SHORT POSITION", IF(AND(LEFT(TRIM(AA11&""),1)<>"3",BI11<>""),"LONG POSITION","ENTRY PENDING"))) -> CLOSE POSITION | F11: =AA11 -> 32015286 | H11: =AB11 -> MOI COMMODITIES INDIA PVT LTD | I11: BURKINA FASO | J11: INDIA | K11: =IF(BQ11<>0,BQ11,"") -> MUNDRA, INDIA | L11: =IF(BI11<>0,BI11,"") -> ONEYTEMG00307500 | M11: =IF(BJ11<>0,BJ11,"") -> 182.57 | N11: =IF(BM11<>0,BM11,"") -> 46125 | O11: =IF(BO11<>0,BO11,"") -> 46163 | P11: =CE11 -> OBL In Destination - INDIA | R11: =CK11 -> CERT in Transit to -INDIA | S11: =CP11 -> Docs in Buyer's Nego Bank | U11: PAYMENT RCVD 27/05 | W11: PAYMENT PENDING-CERTS WILL REACH 2ND JUNE | X11: 46134 | Y11: 20009765 | Z11: 46098 | AA11: 32015286 | AB11: MOI COMMODITIES INDIA PVT LTD | AC11: March /15th April | AD11: 46127 | AE11: 0.1 | AF11: 200 | AG11: =AF11*(1-AE11) -> 180 | AH11: MT | AI11: 1485 | AJ11: =AI11*AF11 -> 297000 | AK11: CIF | AL11: 10% ADVANCE 90%DP AT SIGHT | AM11: 0.1 | AN11: 0.9 | AO11: 0 | AP11: 180 DAYS | AQ11: Mr. George | AR11: Direct | AT11: - | AU11: - | AV11: - | AZ11: =AF11*AI11*AM11 -> 29700 | BA11: 46105 | BB11: 46099 | BF11: 46099 | BI11: ONEYTEMG00307500 | BJ11: 182.57 | BK11: 40' | BL11: 7 | BM11: 46125 | BO11: 46163 | BP11: TEMA, GHANA | BQ11: MUNDRA, INDIA | BR11: ONE LINE | BT11: SPIL KARTIKA | BU11: 2609E | BV11: 90085007 | BW11: 46125 | BX11: =BJ11*AI11 -> 271116.45 | BZ11: 46137 | CA11: 5182275906 | CB11: 46146 | CE11: =IF(J11="VIETNAM", IF(CG11<>"","OBL in Vietnam Office", IF(CF11<>"","OBL in Transit from Vietnam Office", IF(CD11<>0,"OBL In Destination - "&J11, IF(CC11<>0,"OBL in Transit to Destination - "&J11, IF(CB11<>0,"OBL in SIG Office", IF(CA11<>0,"OBL in Transit from Origin to SIG", IF(BZ11<>0,"OBL in Origin - "&I11, IF(BY11<>0,"Draft Rcvd","No OBL Yet")))))))), IF(CO11<>0,"OBL In Destination - "&J11, IF(CM11<>0,"OBL in Transit with Nego Docs - "&J11, IF(CB11<>0,"OBL in SIG Office", IF(CA11<>0,"OBL in Transit from Origin to SIG", IF(BZ11<>0,"OBL in Origin - "&I11, IF(BY11<>0,"Draft Rcvd","No OBL Yet"))))))) -> OBL In Destination - INDIA | CH11: 46164 | CI11: 6696514112 FUMI / 1377954734 LDC/PHYTO | CK11: =IF(CJ11<>0,"CERTS in Destination - "&J11,IF(CI11<>0,"CERT in Transit to -"&J11,IF(CH11<>0,"CERT in Origin - "&I11,IF(CH11="","No CERTS Yet")))) -> CERT in Transit to -INDIA | CL11: HABIB BANK | CM11: 46146 | CN11: 6065372143 | CO11: 46148 | CP11: =IF(CO11<>0,"Docs in Buyer's Nego Bank",IF(CN11<>0,"Docs in Transit to Buyer's Nego Bank",IF(CM11<>0,"Docs in Our Nego Bank",IF(CL11="TT PAYMENT","Not Applicable","")))) -> Docs in Buyer's Nego Bank | CQ11: 241416.45 | CR11: 46169 | CU11: =IF(CS11="","",BJ11-CT11) | CV11: =IF(CS11="","",CU11/BJ11) | CW11: =IF(CS11="","",AZ11+CQ11) | CX11: =IF(CS11="","",BX11*2%) | CY11: =IF(CS11="","",AI11/B11) | DA11: =IF(CS11="","",B11-CZ11) | DC11: =IF(CS11="","",IF(CS11="","",DB11-C11)) | DE11: =IF(CS11="","",10%-DD11) | DF11: =IF(CS11="","",CU11*AI11) | DG11: =IF(CS11="","",IF(DA11>2,2*DA11*CT11*CY11,DA11*CT11*CY11)) | DH11: =IF(CS11="","",IF(DA11>2,2*(DA11-2*CT11*CY11),0)) | DI11: =IF(CS11="","",IF(DC11>0,DC11*0.5*CT11,0)) | DJ11: =IF(CS11="","",IF(DE11<0,DE11*CT11*AI11*1%,0)) | DK11: =IF(CS11="","",SUM(DF11:DJ11)) | DN11: =IF(CS11="","",SUM(DK11:DL11)) | DO11: =IF(CS11="","",BJ11*AI11-DN11) | DP11: =IF(CS11="","",AZ11+CQ11) | DQ11: =IF(CS11="","",IF((DP11-DO11)>0,DP11-DO11,"")) | DR11: =IF(CS11="","",IF((DO11-DP11)>0,(DO11-DP11),"")) | DS11: =IF(CS11="","",IF(DQ11="",H11,"VALENCY")) | DT11: =IF(DN11="","",IF(DN11>0,"CN", "DN")) | DY11: NO VINA/RBS REPORT | EA11: =IF(CS11="","", MIN(0,(IF(DA11>2,2,1)*DA11*CT11*CY11)) ) | EE11: 4900009632 | EH11: VALORA BURKINA EXIM SARL | EJ11: =BJ11 -> 182.57 | EK11: 1200 | EN11: =EK11*EJ11 -> 219084 | EV11: =IF(CR11<>0,"Final Pmt Recd",IF(CM11<>0,"Export Loan",IF(BZ11<>0,"Nego Pending",IF(Z11<>0,"Yet to load","Yet to load")))) -> Final Pmt Recd | EX11: =EW11/BJ11 -> 0 | EY11: Freight paid by origin | FA11: 22141468 | FD11: =FC11*BJ11 -> 0 | FL11: =IFERROR(EZ11-BY11,"") -> 0 | FM11: =IFERROR(BM11-FB11,"") -> 46125 | FS11: =Y11 -> 20009765 | FT11: =AA11 -> 32015286
A12: =IF(DZ12="CLOSE","Trade closed",IF(DZ12="PMT Pending","FNF Settlement is Due",IF(CS12<>0,"FNF Reconcillation Onging",IF(CR12<>0," Final Pmt Recd , FNF Pending",IF(CM12<>0,"Exp Dox Presented to Bank, Pmt Pending",IF(BZ12<>0,"OBL Scan Recd, Nego Pending",IF(BM12<>0,"Sailed, OBL & Certs Pending",IF(BJ12<>0,"Stuffed, Yet to Sail",IF(BB12<>0,"SI Sent, Shipment Awaited",IF(BA12<>0,"Advance Rcvd, SI Pending",IF(Z12<>0,"SC Raised, Advance Pending",IF(X12<>0,"Deal Ticket Rcvd SC Pending", "Entry Pending")))))))))))) -> Exp Dox Presented to Bank, Pmt Pending | B12: 50 | C12: 185 | D12: RCN | E12: =IF(AND(LEFT(TRIM(AA12&""),1)="3",BI12<>""),"CLOSE POSITION", IF(AND(LEFT(TRIM(AA12&""),1)="3",BI12=""),"SHORT POSITION", IF(AND(LEFT(TRIM(AA12&""),1)<>"3",BI12<>""),"LONG POSITION","ENTRY PENDING"))) -> CLOSE POSITION | F12: =AA12 -> 32014448-3 | H12: =AB12 -> Valency Agro (Processing) | I12: NIGERIA(OGB) | J12: INDIA | K12: =IF(BQ12<>0,BQ12,"") -> MANGALORE, INDIA | L12: =IF(BI12<>0,BI12,"") -> MEDULG626012 | M12: =IF(BJ12<>0,BJ12,"") -> 105.235 | N12: =IF(BM12<>0,BM12,"") -> 46110 | O12: =IF(BO12<>0,BO12,"") -> 46157 | P12: =CE12 -> OBL In Destination - INDIA | R12: =CK12 -> CERTS in Destination - INDIA | S12: =CP12 -> Docs in Buyer's Nego Bank | T12: =IFERROR(_xlfn.XLOOKUP(F12, '[2]Data 2026'!$H$12:$H$111, '[2]Data 2026'!$CL$12:$CL$111),"") | U12: Payment by Valency Agro will be done, 90 days after BL date- CARGO CLEARED. | X12: 46066 | Y12: 20009485 | Z12: 46066 | AA12: 32014448-3 | AB12: Valency Agro (Processing) | AC12: 46082 | AD12: 46112 | AE12: 0.1 | AF12: =BJ12 -> 105.235 | AG12: =AF12*(1-AE12) -> 94.7115 | AH12: MT | AI12: 1683 | AJ12: 1700000 | AK12: CIF | AL12: 90 DAYS FROM BL DATE | AM12: 0 | AN12: 1 | AO12: 0 | AP12: 180 DAYS | AQ12: Mr. Naveen | AR12: Direct | AT12: - | AU12: - | AV12: - | AZ12: =AF12*AI12*AM12 -> 0 | BA12: 46069 | BB12: 46073 | BF12: 46073 | BI12: MEDULG626012 | BJ12: 105.235 | BK12: 40' | BL12: 4 | BM12: 46110 | BN12: Vizhinjam international 10-05 | BO12: 46157 | BP12: NIGERIA | BQ12: MANGALORE, INDIA | BR12: MSC | BS12: LASTBORN | BV12: 90084574 | BX12: =BJ12*AI12 -> 177110.51 | BZ12: 46129 | CA12: 4567280594 | CB12: 46132 | CE12: =IF(J12="VIETNAM", IF(CG12<>"","OBL in Vietnam Office", IF(CF12<>"","OBL in Transit from Vietnam Office", IF(CD12<>0,"OBL In Destination - "&J12, IF(CC12<>0,"OBL in Transit to Destination - "&J12, IF(CB12<>0,"OBL in SIG Office", IF(CA12<>0,"OBL in Transit from Origin to SIG", IF(BZ12<>0,"OBL in Origin - "&I12, IF(BY12<>0,"Draft Rcvd","No OBL Yet")))))))), IF(CO12<>0,"OBL In Destination - "&J12, IF(CM12<>0,"OBL in Transit with Nego Docs - "&J12, IF(CB12<>0,"OBL in SIG Office", IF(CA12<>0,"OBL in Transit from Origin to SIG", IF(BZ12<>0,"OBL in Origin - "&I12, IF(BY12<>0,"Draft Rcvd","No OBL Yet"))))))) -> OBL In Destination - INDIA | CH12: 46141 | CI12: 1335828874 | CJ12: 46157 | CK12: =IF(CJ12<>0,"CERTS in Destination - "&J12,IF(CI12<>0,"CERT in Transit to -"&J12,IF(CH12<>0,"CERT in Origin - "&I12,IF(CH12="","No CERTS Yet")))) -> CERTS in Destination - INDIA | CL12: ICICI BANK | CM12: 46139 | CN12: 8585994476 | CO12: 46147 | CP12: =IF(CO12<>0,"Docs in Buyer's Nego Bank",IF(CN12<>0,"Docs in Transit to Buyer's Nego Bank",IF(CM12<>0,"Docs in Our Nego Bank",IF(CL12="TT PAYMENT","Not Applicable","")))) -> Docs in Buyer's Nego Bank | CQ12: =(AN12*AI12*BJ12)-AZ12 -> 177110.51 | CU12: =IF(CS12="","",BJ12-CT12) | CV12: =IF(CS12="","",CU12/BJ12) | CW12: =IF(CS12="","",AZ12+CQ12) | CX12: =IF(CS12="","",BX12*2%) | CY12: =IF(CS12="","",AI12/B12) | DA12: =IF(CS12="","",B12-CZ12) | DC12: =IF(CS12="","",IF(CS12="","",DB12-C12)) | DE12: =IF(CS12="","",10%-DD12) | DF12: =IF(CS12="","",CU12*AI12) | DG12: =IF(CS12="","",IF(DA12>2,2*DA12*CT12*CY12,DA12*CT12*CY12)) | DH12: =IF(CS12="","",IF(DA12>2,2*(DA12-2*CT12*CY12),0)) | DI12: =IF(CS12="","",IF(DC12>0,DC12*0.5*CT12,0)) | DJ12: =IF(CS12="","",IF(DE12<0,DE12*CT12*AI12*1%,0)) | DK12: =IF(CS12="","",SUM(DF12:DJ12)) | DN12: =IF(CS12="","",SUM(DK12:DL12)) | DO12: =IF(CS12="","",BJ12*AI12-DN12) | DP12: =IF(CS12="","",AZ12+CQ12) | DQ12: =IF(CS12="","",IF((DP12-DO12)>0,DP12-DO12,"")) | DR12: =IF(CS12="","",IF((DO12-DP12)>0,(DO12-DP12),"")) | DS12: =IF(CS12="","",IF(DQ12="",H12,"VALENCY")) | DT12: =IF(DN12="","",IF(DN12>0,"CN", "DN")) | DY12: NO VINA/RBS REPORT | EA12: =IF(CS12="","", MIN(0,(IF(DA12>2,2,1)*DA12*CT12*CY12)) ) | EB12: 47.38 | EC12: 191 | ED12: 8.95 | EE12: 4900009113 | EH12: LASTBORN GENERAL MERCHANT LTD | EI12: FOB | EJ12: =BJ12 -> 105.235 | EK12: 1600 | EN12: =EK12*EJ12 -> 168376 | EO12: FOB | ER12: 165008.48 | EV12: =IF(CR12<>0,"Final Pmt Recd",IF(CM12<>0,"Export Loan",IF(BZ12<>0,"Nego Pending",IF(Z12<>0,"Yet to load","Yet to load")))) -> Export Loan | EX12: =EW12/BJ12 -> 0 | EY12: Freight paid by origin | FD12: =FC12*BJ12 -> 0 | FL12: =IFERROR(EZ12-BY12,"") -> 0 | FM12: =IFERROR(BM12-FB12,"") -> 46110 | FS12: =Y12 -> 20009485 | FT12: =AA12 -> 32014448-3
A13: =IF(DZ13="CLOSE","Trade closed",IF(DZ13="PMT Pending","FNF Settlement is Due",IF(CS13<>0,"FNF Reconcillation Onging",IF(CR13<>0," Final Pmt Recd , FNF Pending",IF(CM13<>0,"Exp Dox Presented to Bank, Pmt Pending",IF(BZ13<>0,"OBL Scan Recd, Nego Pending",IF(BM13<>0,"Sailed, OBL & Certs Pending",IF(BJ13<>0,"Stuffed, Yet to Sail",IF(BB13<>0,"SI Sent, Shipment Awaited",IF(BA13<>0,"Advance Rcvd, SI Pending",IF(Z13<>0,"SC Raised, Advance Pending",IF(X13<>0,"Deal Ticket Rcvd SC Pending", "Entry Pending")))))))))))) -> SI Sent, Shipment Awaited | B13: 49 | C13: 200 | D13: RCN | E13: =IF(AND(LEFT(TRIM(AA13&""),1)="3",BI13<>""),"CLOSE POSITION", IF(AND(LEFT(TRIM(AA13&""),1)="3",BI13=""),"SHORT POSITION", IF(AND(LEFT(TRIM(AA13&""),1)<>"3",BI13<>""),"LONG POSITION","ENTRY PENDING"))) -> SHORT POSITION | F13: =AA13 -> 32014482 | H13: =AB13 -> MADHAVARAYA PRABHU | I13: IVC | J13: INDIA | K13: =IF(BQ13<>0,BQ13,"") -> MANGALORE, INDIA | L13: =IF(BI13<>0,BI13,"") | M13: =IF(BJ13<>0,BJ13,"") | N13: =IF(BM13<>0,BM13,"") | O13: =IF(BO13<>0,BO13,"") | P13: =CE13 -> No OBL Yet | R13: =CK13 -> No CERTS Yet | S13: =CP13 | T13: CLARIFICATION ON LATEST SOB | U13: RCVD COUNTERSIGNED-267489781 267489781-1 | X13: 46073 | Y13: 20009534 | Z13: 46073 | AA13: 32014482 | AB13: MADHAVARAYA PRABHU | AC13: April - 26 | AD13: 46142 | AE13: 0.1 | AF13: 200 | AG13: =AF13*(1-AE13) -> 180 | AH13: MT | AI13: 1545 | AJ13: =AI13*AF13 -> 309000 | AK13: CIF | AL13: DP SIGHT | AM13: 0 | AN13: 1 | AO13: 0 | AP13: 180 DAYS | AQ13: Mr. George | AR13: Mr. Rao | AS13: 5 | AT13: - | AU13: - | AV13: - | AZ13: =AF13*AI13*AM13 -> 0 | BA13: 46076 | BB13: 46083 | BF13: 46083 | BK13: 40' | BP13: IVC | BQ13: MANGALORE, INDIA | BX13: =BJ13*AI13 -> 0 | CE13: =IF(J13="VIETNAM", IF(CG13<>"","OBL in Vietnam Office", IF(CF13<>"","OBL in Transit from Vietnam Office", IF(CD13<>0,"OBL In Destination - "&J13, IF(CC13<>0,"OBL in Transit to Destination - "&J13, IF(CB13<>0,"OBL in SIG Office", IF(CA13<>0,"OBL in Transit from Origin to SIG", IF(BZ13<>0,"OBL in Origin - "&I13, IF(BY13<>0,"Draft Rcvd","No OBL Yet")))))))), IF(CO13<>0,"OBL In Destination - "&J13, IF(CM13<>0,"OBL in Transit with Nego Docs - "&J13, IF(CB13<>0,"OBL in SIG Office", IF(CA13<>0,"OBL in Transit from Origin to SIG", IF(BZ13<>0,"OBL in Origin - "&I13, IF(BY13<>0,"Draft Rcvd","No OBL Yet"))))))) -> No OBL Yet | CK13: =IF(CJ13<>0,"CERTS in Destination - "&J13,IF(CI13<>0,"CERT in Transit to -"&J13,IF(CH13<>0,"CERT in Origin - "&I13,IF(CH13="","No CERTS Yet")))) -> No CERTS Yet | CP13: =IF(CO13<>0,"Docs in Buyer's Nego Bank",IF(CN13<>0,"Docs in Transit to Buyer's Nego Bank",IF(CM13<>0,"Docs in Our Nego Bank",IF(CL13="TT PAYMENT","Not Applicable","")))) | CQ13: =(AN13*AI13*BJ13)-AZ13 -> 0 | CU13: =IF(CS13="","",BJ13-CT13) | CV13: =IF(CS13="","",CU13/BJ13) | CW13: =IF(CS13="","",AZ13+CQ13) | CX13: =IF(CS13="","",BX13*2%) | CY13: =IF(CS13="","",AI13/B13) | DA13: =IF(CS13="","",B13-CZ13) | DC13: =IF(CS13="","",IF(CS13="","",DB13-C13)) | DE13: =IF(CS13="","",10%-DD13) | DF13: =IF(CS13="","",CU13*AI13) | DG13: =IF(CS13="","",IF(DA13>2,2*DA13*CT13*CY13,DA13*CT13*CY13)) | DH13: =IF(CS13="","",IF(DA13>2,2*(DA13-2*CT13*CY13),0)) | DI13: =IF(CS13="","",IF(DC13>0,DC13*0.5*CT13,0)) | DJ13: =IF(CS13="","",IF(DE13<0,DE13*CT13*AI13*1%,0)) | DK13: =IF(CS13="","",SUM(DF13:DJ13)) | DN13: =IF(CS13="","",SUM(DK13:DL13)) | DO13: =IF(CS13="","",BJ13*AI13-DN13) | DP13: =IF(CS13="","",AZ13+CQ13) | DQ13: =IF(CS13="","",IF((DP13-DO13)>0,DP13-DO13,"")) | DR13: =IF(CS13="","",IF((DO13-DP13)>0,(DO13-DP13),"")) | DS13: =IF(CS13="","",IF(DQ13="",H13,"VALENCY")) | DT13: =IF(DN13="","",IF(DN13>0,"CN", "DN")) | DY13: NO VINA/RBS REPORT | EA13: =IF(CS13="","", MIN(0,(IF(DA13>2,2,1)*DA13*CT13*CY13)) ) | EH13: VALENCY IVC | EN13: =EK13*EJ13 -> 0 | EV13: =IF(CR13<>0,"Final Pmt Recd",IF(CM13<>0,"Export Loan",IF(BZ13<>0,"Nego Pending",IF(Z13<>0,"Yet to load","Yet to load")))) -> Yet to load | EX13: =EW13/BJ13 -> #DIV/0! | EY13: Freight paid by origin | FD13: =FC13*BJ13 -> 0 | FL13: =IFERROR(EZ13-BY13,"") -> 0 | FM13: =IFERROR(BM13-FB13,"") -> 0 | FS13: =Y13 -> 20009534 | FT13: =AA13 -> 32014482
A14: =IF(DZ14="CLOSE","Trade closed",IF(DZ14="PMT Pending","FNF Settlement is Due",IF(CS14<>0,"FNF Reconcillation Onging",IF(CR14<>0," Final Pmt Recd , FNF Pending",IF(CM14<>0,"Exp Dox Presented to Bank, Pmt Pending",IF(BZ14<>0,"OBL Scan Recd, Nego Pending",IF(BM14<>0,"Sailed, OBL & Certs Pending",IF(BJ14<>0,"Stuffed, Yet to Sail",IF(BB14<>0,"SI Sent, Shipment Awaited",IF(BA14<>0,"Advance Rcvd, SI Pending",IF(Z14<>0,"SC Raised, Advance Pending",IF(X14<>0,"Deal Ticket Rcvd SC Pending", "Entry Pending")))))))))))) -> Exp Dox Presented to Bank, Pmt Pending | B14: 50 | C14: 185 | D14: RCN | E14: =IF(AND(LEFT(TRIM(AA14&""),1)="3",BI14<>""),"CLOSE POSITION", IF(AND(LEFT(TRIM(AA14&""),1)="3",BI14=""),"SHORT POSITION", IF(AND(LEFT(TRIM(AA14&""),1)<>"3",BI14<>""),"LONG POSITION","ENTRY PENDING"))) -> CLOSE POSITION | F14: =AA14 -> 32014448-5 | H14: =AB14 -> Valency Agro (Processing) | I14: NIGERIA(OGB) | J14: INDIA | K14: =IF(BQ14<>0,BQ14,"") -> MANGALORE, INDIA | L14: =IF(BI14<>0,BI14,"") -> MEDULG625659 | M14: =IF(BJ14<>0,BJ14,"") -> 104.27 | N14: =IF(BM14<>0,BM14,"") -> 46108 | O14: =IF(BO14<>0,BO14,"") -> 46157 | P14: =CE14 -> OBL In Destination - INDIA | R14: =CK14 -> CERTS in Destination - INDIA | S14: =CP14 -> Docs in Buyer's Nego Bank | T14: =IFERROR(_xlfn.XLOOKUP(F14, '[2]Data 2026'!$H$12:$H$111, '[2]Data 2026'!$CL$12:$CL$111),"") | U14: Payment by Valency Agro will be done, 90 days after BL date- CARGO CLEARED. | X14: 46066 | Y14: 20009485 | Z14: 46066 | AA14: 32014448-5 | AB14: Valency Agro (Processing) | AC14: 46082 | AD14: 46112 | AE14: 0.1 | AF14: =BJ14 -> 104.27 | AG14: =AF14*(1-AE14) -> 93.843 | AH14: MT | AI14: 1683 | AJ14: 1700000 | AK14: CIF | AL14: 90 DAYS FROM BL DATE | AM14: 0 | AN14: 1 | AO14: 0 | AP14: 180 DAYS | AQ14: Mr. Naveen | AR14: Direct | AT14: - | AU14: - | AV14: - | AZ14: =AF14*AI14*AM14 -> 0 | BA14: 46069 | BB14: 46073 | BF14: 46073 | BI14: MEDULG625659 | BJ14: 104.27 | BK14: 40' | BL14: 4 | BM14: 46108 | BN14: Vizhinjam internation 04-05 | BO14: 46157 | BP14: NIGERIA | BQ14: MANGALORE, INDIA | BR14: MSC | BS14: LASTBORN | BV14: 90084573 | BX14: =BJ14*AI14 -> 175486.41 | BZ14: 46129 | CA14: 4567280594 | CB14: 46134 | CE14: =IF(J14="VIETNAM", IF(CG14<>"","OBL in Vietnam Office", IF(CF14<>"","OBL in Transit from Vietnam Office", IF(CD14<>0,"OBL In Destination - "&J14, IF(CC14<>0,"OBL in Transit to Destination - "&J14, IF(CB14<>0,"OBL in SIG Office", IF(CA14<>0,"OBL in Transit from Origin to SIG", IF(BZ14<>0,"OBL in Origin - "&I14, IF(BY14<>0,"Draft Rcvd","No OBL Yet")))))))), IF(CO14<>0,"OBL In Destination - "&J14, IF(CM14<>0,"OBL in Transit with Nego Docs - "&J14, IF(CB14<>0,"OBL in SIG Office", IF(CA14<>0,"OBL in Transit from Origin to SIG", IF(BZ14<>0,"OBL in Origin - "&I14, IF(BY14<>0,"Draft Rcvd","No OBL Yet"))))))) -> OBL In Destination - INDIA | CH14: 46141 | CI14: 1335828874 | CJ14: 46157 | CK14: =IF(CJ14<>0,"CERTS in Destination - "&J14,IF(CI14<>0,"CERT in Transit to -"&J14,IF(CH14<>0,"CERT in Origin - "&I14,IF(CH14="","No CERTS Yet")))) -> CERTS in Destination - INDIA | CL14: ICICI BANK | CM14: 46139 | CN14: 8585994476 | CO14: 46147 | CP14: =IF(CO14<>0,"Docs in Buyer's Nego Bank",IF(CN14<>0,"Docs in Transit to Buyer's Nego Bank",IF(CM14<>0,"Docs in Our Nego Bank",IF(CL14="TT PAYMENT","Not Applicable","")))) -> Docs in Buyer's Nego Bank | CQ14: =(AN14*AI14*BJ14)-AZ14 -> 175486.41 | CU14: =IF(CS14="","",BJ14-CT14) | CV14: =IF(CS14="","",CU14/BJ14) | CW14: =IF(CS14="","",AZ14+CQ14) | CX14: =IF(CS14="","",BX14*2%) | CY14: =IF(CS14="","",AI14/B14) | DA14: =IF(CS14="","",B14-CZ14) | DC14: =IF(CS14="","",IF(CS14="","",DB14-C14)) | DE14: =IF(CS14="","",10%-DD14) | DF14: =IF(CS14="","",CU14*AI14) | DG14: =IF(CS14="","",IF(DA14>2,2*DA14*CT14*CY14,DA14*CT14*CY14)) | DH14: =IF(CS14="","",IF(DA14>2,2*(DA14-2*CT14*CY14),0)) | DI14: =IF(CS14="","",IF(DC14>0,DC14*0.5*CT14,0)) | DJ14: =IF(CS14="","",IF(DE14<0,DE14*CT14*AI14*1%,0)) | DK14: =IF(CS14="","",SUM(DF14:DJ14)) | DN14: =IF(CS14="","",SUM(DK14:DL14)) | DO14: =IF(CS14="","",BJ14*AI14-DN14) | DP14: =IF(CS14="","",AZ14+CQ14) | DQ14: =IF(CS14="","",IF((DP14-DO14)>0,DP14-DO14,"")) | DR14: =IF(CS14="","",IF((DO14-DP14)>0,(DO14-DP14),"")) | DS14: =IF(CS14="","",IF(DQ14="",H14,"VALENCY")) | DT14: =IF(DN14="","",IF(DN14>0,"CN", "DN")) | DY14: NO VINA/RBS REPORT | EA14: =IF(CS14="","", MIN(0,(IF(DA14>2,2,1)*DA14*CT14*CY14)) ) | EB14: 47.95 | EC14: 192 | ED14: 8.58 | EE14: 4900009113 | EH14: LASTBORN GENERAL MERCHANT LTD | EI14: FOB | EJ14: =BJ14 -> 104.27 | EK14: 1600 | EN14: =EK14*EJ14 -> 166832 | EO14: FOB | ER14: 163495.36 | EV14: =IF(CR14<>0,"Final Pmt Recd",IF(CM14<>0,"Export Loan",IF(BZ14<>0,"Nego Pending",IF(Z14<>0,"Yet to load","Yet to load")))) -> Export Loan | EX14: =EW14/BJ14 -> 0 | EY14: Freight paid by origin | FD14: =FC14*BJ14 -> 0 | FL14: =IFERROR(EZ14-BY14,"") -> 0 | FM14: =IFERROR(BM14-FB14,"") -> 46108 | FS14: =Y14 -> 20009485 | FT14: =AA14 -> 32014448-5
